Workbook

Sheet RESUMEN DIPLOMADO
D1: CENTRO DE EDUCACIÓN CONTINUA
D2: UNIDAD DE CAPACITACIÓN Y CERTIFICACIÓN
D3: DIPLOMADO EN BIG DATA E INTELIGENCIA ARTIFICIAL | K3: Duración total del diplomado (Horas) | M3: 150 horas 120 horas sincrónicas y 30 horas asincrónicas
A5: Descripción general del diplomado | B5: El Diplomado en Big Data e Inteligencia Artificial ha sido diseñado para fortalecer las capacidades técnicas y analíticas de los profesionales vinculados al análisis económico, estadístico y tecnológico, mediante el uso de herramientas modernas de ciencia de datos, machine learning e inteligencia artificial aplicadas al análisis macroeconómico y la toma de decisiones institucionales. El programa integra fundamentos teóricos y prácticos relacionados con programación, automatización, analítica avanzada, modelamiento econométrico y técnicas de forecasting. A través de metodologías activas y laboratorios prácticos, los participantes desarrollarán competencias para gestionar grandes volúmenes de datos, automatizar procesos de recolección de información, construir modelos predictivos y generar análisis económicos avanzados mediante R y Python. El diplomado permitirá fortalecer la innovación institucional y optimizar procesos de análisis económico mediante tecnologías emergentes, contribuyendo a la generación de información estratégica para la toma de decisiones en el sector público y financiero.
A6: Dirigido a | B6: El diplomado está dirigido al personal operativo, mandos medios y profesionales de cuarto nivel del área de estudios y programación económica del Banco Central del Ecuador, así como a analistas económicos, estadísticos, investigadores, especialistas en datos y profesionales vinculados al análisis cuantitativo, automatización de procesos y generación de proyecciones económicas.
A7: Requisitos académicos (Perfil del estudiantes) | B7: Los participantes deberán poseer título de tercer o cuarto nivel en Economía, Estadística, Matemáticas, Ingeniería, Computación, Finanzas, Ciencia de Datos o carreras afines. Se recomienda experiencia básica en análisis de datos, estadística descriptiva y uso de herramientas informáticas.
A8: Requisitos técnicos | B8: Computador portátil o de escritorio con procesador Intel Core i5 o superior. Memoria RAM mínima de 8 GB. Espacio libre en disco de al menos 30 GB. Conexión estable a internet de mínimo 10 Mbps. Cámara web y micrófono funcional. Sistema operativo Windows 10 o superior, Linux o macOS. Navegador actualizado. Instalación de R, RStudio, Python y Jupyter Notebook. Acceso a plataformas colaborativas y videoconferencia.
A9: Objetivo General del Diplomado | B9: Desarrollar capacidades técnicas en Big Data e Inteligencia Artificial mediante herramientas de programación, machine learning y analítica avanzada en contextos de análisis económico y estadístico, para fortalecer la automatización de procesos y la toma de decisiones basada en datos.
A10: Nombre del módulo | B10: =+'MODULO 1 '!B5:F5 -> MÓDULO 1. FUNDAMENTOS DE BIG DATA E INTELIGENCIA ARTIFICIAL | E10: =+'MODULO 2 '!B5 -> MÓDULO 2. PROGRAMACIÓN Y GESTIÓN DE DATOS MASIVOS | H10: =+'MODULO 3'!B5 -> MÓDULO 3. MACHINE LEARNING APLICADO | K10: =+'MODULO 4'!B5 -> MÓDULO 4. IA PARA AUTOMATIZACIÓN Y RECOLECCIÓN DE DATOS | N10: =+'MODULO 5'!B5 -> MÓDULO 5. ECONOMETRÍA Y FORECASTING CON IA | Q10: =+'MODULO 6'!B5 -> MÓDULO 6. MODELOS AVANZADOS DE IA Y APLICACIONES ECONÓMICAS
A11: Duración (Horas) | B11: =+'MODULO 1 '!H5 -> 25 horas (20 horas sincrónicas y 5 horas asincrónicas) | E11: =+'MODULO 2 '!H5 -> 25 horas (20 horas sincrónicas y 5 horas asincrónicas) | H11: =+'MODULO 3'!H5 -> 25 horas (20 horas sincrónicas y 5 horas asincrónicas) | K11: =+'MODULO 4'!H5 -> 25 horas (20 horas sincrónicas y 5 horas asincrónicas) | N11: =+'MODULO 5'!H5 -> 25 horas (20 horas sincrónicas y 5 horas asincrónicas) | Q11: =+'MODULO 6'!H5 -> 25 horas (20 horas sincrónicas y 5 horas asincrónicas)
A12: Presentación del módulo | B12: =+'MODULO 1 '!B6:H6 -> Este módulo introduce los conceptos fundamentales relacionados con Big Data, Inteligencia Artificial y Machine Learning, proporcionando una visión integral sobre el impacto de estas tecnologías en los procesos de análisis económico y toma de decisiones. Los participantes comprenderán los principales paradigmas de aprendizaje automático y su aplicación en escenarios institucionales. El módulo permitirá desarrollar capacidades para interpretar el ciclo de vida de proyectos de analítica avanzada y comprender el valor estratégico de los datos en organizaciones modernas. Los participantes adquirirán conocimientos sobre tipos de aprendizaje supervisado y no supervisado, ecosistemas de IA y aplicaciones en economía. Al finalizar, el estudiante será capaz de identificar oportunidades de implementación de IA y Big Data en contextos institucionales y económicos. | E12: =+'MODULO 2 '!B6 -> Este módulo desarrolla competencias relacionadas con programación orientada al análisis de datos, gestión de bases de datos masivas y procesamiento de información estructurada y no estructurada. Los participantes aprenderán técnicas de limpieza, transformación y manipulación de datos utilizando R y Python. La propuesta de valor del módulo radica en fortalecer capacidades técnicas para automatizar procesos de análisis y preparación de datos, optimizando la calidad de la información utilizada en estudios económicos y estadísticos. Al finalizar, los estudiantes estarán en capacidad de desarrollar flujos de procesamiento de datos y construir estructuras de análisis reproducibles. | H12: =+'MODULO 3'!B6 -> Este módulo aborda las técnicas de machine learning aplicadas al análisis predictivo, clasificación y segmentación de datos económicos. Los participantes desarrollarán modelos supervisados y no supervisados utilizando herramientas modernas de ciencia de datos. El módulo permitirá fortalecer competencias analíticas para generar modelos predictivos orientados a forecasting económico y toma de decisiones. Al finalizar, los participantes podrán construir modelos de regresión, clasificación y clustering aplicados a problemas institucionales y económicos. | K12: =+'MODULO 4'!B6 -> Este módulo desarrolla competencias para automatizar procesos de captura, integración y procesamiento de información mediante herramientas de inteligencia artificial, APIs y web scraping. Los participantes aprenderán a construir flujos automatizados para la obtención y procesamiento de datos económicos. El módulo permitirá optimizar procesos institucionales relacionados con actualización de bases de datos, monitoreo de indicadores y generación automática de reportes. Al finalizar, los estudiantes estarán en capacidad de implementar soluciones automatizadas para recolección y análisis de información. | N12: =+'MODULO 5'!B6 -> Este módulo integra técnicas econométricas tradicionales con modelos de machine learning orientados al forecasting económico y análisis predictivo. Los participantes aprenderán a construir modelos híbridos para mejorar precisión en estimaciones macroeconómicas. La propuesta de valor del módulo radica en fortalecer competencias para analizar series de tiempo, realizar proyecciones económicas y comparar metodologías predictivas. Al finalizar, los estudiantes estarán en capacidad de construir modelos econométricos y de IA aplicados a variables económicas reales. | Q12: =+'MODULO 6'!B6 -> Este módulo aborda técnicas avanzadas de inteligencia artificial, incluyendo modelos bayesianos, algoritmos no paramétricos e introducción a deep learning aplicados al análisis económico y predictivo. Los participantes integrarán conocimientos adquiridos durante el diplomado para resolver problemas complejos mediante analítica avanzada. El módulo permitirá fortalecer capacidades para implementar soluciones innovadoras orientadas a la toma de decisiones estratégicas y análisis económico avanzado. Al finalizar, los estudiantes estarán preparados para aplicar técnicas avanzadas de IA en escenarios institucionales y proyectos de innovación pública.
A13: Objetivo General | B13: =+'MODULO 1 '!B11:H11 -> Comprender los fundamentos de Big Data e Inteligencia Artificial mediante conceptos y herramientas tecnológicas en contextos de análisis económico, para identificar aplicaciones orientadas a la toma de decisiones basada en datos. | E13: =+'MODULO 2 '!B11 -> Gestionar datos masivos mediante herramientas de programación y procesamiento en contextos analíticos institucionales, para optimizar la calidad y disponibilidad de información económica. | H13: =+'MODULO 3'!B11 -> Aplicar modelos de machine learning mediante técnicas predictivas y herramientas analíticas en escenarios económicos, para generar pronósticos y clasificaciones basadas en datos. | K13: =+'MODULO 4'!B11 -> Automatizar procesos de recolección y procesamiento de datos mediante herramientas de IA y programación en contextos analíticos institucionales, para optimizar generación de información económica. | N13: =+'MODULO 5'!B11 -> Construir modelos econométricos y de forecasting mediante técnicas estadísticas y machine learning en contextos económicos, para mejorar predicción y análisis de variables macroeconómicas. | Q13: =+'MODULO 6'!B11 -> Aplicar modelos avanzados de inteligencia artificial mediante técnicas analíticas y herramientas predictivas en escenarios económicos, para generar soluciones innovadoras orientadas a la toma de decisiones.
A14: Objetivos Específicos | B14: =+'MODULO 1 '!B12:H12 -> U1. Identificar conceptos fundamentales de IA mediante análisis de aplicaciones tecnológicas en contextos económicos para comprender su impacto institucional. U2. Analizar tipos de machine learning mediante modelos supervisados y no supervisados en escenarios analíticos para diferenciar enfoques predictivos. U3. Reconocer ecosistemas Big Data mediante plataformas y arquitecturas de datos en entornos organizacionales para comprender su funcionamiento. U4. Relacionar analítica avanzada mediante casos económicos institucionales para identificar oportunidades de innovación. Aplicar herramientas básicas de IA mediante laboratorios prácticos en análisis económico para interpretar resultados analíticos. | E14: =+'MODULO 2 '!B12 -> U1. Aplicar fundamentos de programación mediante R y Python en escenarios analíticos para automatizar procesos de datos. U2. Gestionar bases de datos mediante técnicas ETL en entornos institucionales para optimizar calidad de información. U2. Limpiar y transformar datos mediante librerías analíticas en proyectos económicos para mejorar consistencia de resultados. U3. Analizar datos estructurados y no estructurados mediante herramientas de procesamiento para generar información útil. U4. Desarrollar flujos automatizados mediante programación aplicada en casos institucionales para optimizar análisis económico. | H14: =+'MODULO 3'!B12 -> Construir modelos de regresión mediante algoritmos supervisados en análisis económicos para generar predicciones. Aplicar técnicas de clasificación mediante machine learning en conjuntos de datos institucionales para identificar patrones. Implementar modelos de clustering mediante algoritmos no supervisados en análisis de segmentación para interpretar comportamientos. Evaluar desempeño de modelos mediante métricas analíticas en proyectos predictivos para optimizar resultados. Desarrollar soluciones predictivas mediante laboratorios aplicados en escenarios económicos para fortalecer toma de decisiones. | K14: =+'MODULO 4'!B12 -> U1. Implementar técnicas de web scraping mediante programación en plataformas web para automatizar captura de información. U2. Utilizar APIs mediante herramientas tecnológicas en análisis económicos para integrar fuentes de datos. U3. Automatizar procesos analíticos mediante scripts y flujos de trabajo en escenarios institucionales para optimizar productividad. U4. Aplicar agentes inteligentes mediante herramientas de IA en procesos de datos para mejorar eficiencia operativa. U5. Desarrollar soluciones automatizadas mediante casos prácticos institucionales para fortalecer análisis económico. | N14: =+'MODULO 5'!B12 -> U1. Analizar series temporales mediante modelos econométricos en escenarios económicos para generar proyecciones. U2. Aplicar modelos ARIMA mediante herramientas analíticas en forecasting económico para estimar tendencias. U3. Integrar machine learning mediante técnicas predictivas en modelos econométricos para optimizar precisión. U4. Evaluar desempeño predictivo mediante métricas analíticas en proyecciones económicas para validar resultados. U5. Desarrollar modelos híbridos mediante casos institucionales para fortalecer análisis macroeconómico. | Q14: =+'MODULO 6'!B12 -> U1. Implementar modelos no paramétricos mediante algoritmos avanzados en análisis económicos para optimizar predicciones. U2. Aplicar técnicas bayesianas mediante modelos probabilísticos en escenarios institucionales para fortalecer análisis de incertidumbre. U3. Comprender fundamentos de deep learning mediante redes neuronales en problemas predictivos para identificar aplicaciones avanzadas. U4. Analizar aplicaciones económicas mediante IA avanzada en contextos macroeconómicos para generar valor institucional. Desarrollar proyectos integradores mediante técnicas avanzadas en escenarios reales para fortalecer innovación analítica.
A15: CONTENIDO | B15: =+'MODULO 1 '!B13 -> Unidad 1. Introducción a Big Data (5 horas) | C15: 1.1 | D15: =+'MODULO 1 '!D13:H13 -> Conceptos de Big Data. | E15: =+'MODULO 2 '!B13 -> Unidad 1. Programación en Python y R (5 horas) | F15: 1.1 | G15: =+'MODULO 2 '!D13 -> Sintaxis básica. | H15: =+'MODULO 3'!B13 -> Unidad 1. Regresión y Predicción (5 horas) | I15: 1.1 | J15: =+'MODULO 3'!D13 -> Regresión lineal. | K15: =+'MODULO 4'!B13 -> Unidad 1. Web Scraping (5 horas) | L15: 1.1 | M15: =+'MODULO 4'!D13 -> Introducción al scraping. | N15: =+'MODULO 5'!B13 -> Unidad 1. Series de Tiempo (5 horas) | O15: 1.1 | P15: =+'MODULO 5'!D13 -> Componentes de series. | Q15: =+'MODULO 6'!B13 -> Unidad 1. Modelos No Paramétricos (5 horas) | R15: 1.1 | S15: =+'MODULO 6'!D13 -> KNN.
C16: 1.2 | D16: =+'MODULO 1 '!D14:H14 -> Características de los datos masivos. | F16: 1.2 | G16: =+'MODULO 2 '!D14 -> Variables y estructuras. | I16: 1.2 | J16: =+'MODULO 3'!D14 -> Regresión múltiple. | L16: 1.2 | M16: =+'MODULO 4'!D14 -> BeautifulSoup. | O16: 1.2 | P16: =+'MODULO 5'!D14 -> Estacionalidad. | R16: 1.2 | S16: =+'MODULO 6'!D14 -> Kernel methods.
C17: 1.3 | D17: =+'MODULO 1 '!D15:H15 -> Ecosistemas de datos. | F17: 1.3 | G17: =+'MODULO 2 '!D15 -> Funciones. | I17: 1.3 | J17: =+'MODULO 3'!D15 -> Evaluación predictiva. | L17: 1.3 | M17: =+'MODULO 4'!D15 -> Selenium. | O17: 1.3 | P17: =+'MODULO 5'!D15 -> Tendencia. | R17: 1.3 | S17: =+'MODULO 6'!D15 -> Árboles avanzados.
C18: 1.4 | D18: =+'MODULO 1 '!D16:H16 -> Transformación digital. | F18: 1.4 | G18: =+'MODULO 2 '!D16 -> Librerías analíticas. | I18: 1.4 | J18: =+'MODULO 3'!D16 -> Overfitting. | L18: 1.4 | M18: =+'MODULO 4'!D16 -> Extracción de tablas. | O18: 1.4 | P18: =+'MODULO 5'!D16 -> Estacionariedad. | R18: 1.4 | S18: =+'MODULO 6'!D16 -> Boosting.
C19: 1.5 | D19: =+'MODULO 1 '!D17:H17 -> Aplicaciones institucionales. | F19: 1.5 | G19: =+'MODULO 2 '!D17 -> Automatización básica. | I19: 1.5 | J19: =+'MODULO 3'!D17 -> Validación cruzada. | L19: 1.5 | M19: =+'MODULO 4'!D17 -> Automatización web. | O19: 1.5 | P19: =+'MODULO 5'!D17 -> Visualización temporal. | R19: 1.5 | S19: =+'MODULO 6'!D17 -> Bagging.
B20: =+'MODULO 1 '!B18 -> Unidad 2. Fundamentos de Inteligencia Artificial (5 horas) | C20: 2.1 | D20: =+'MODULO 1 '!D18:H18 -> Historia y evolución de la IA. | E20: =+'MODULO 2 '!B18 -> Unidad 2. Manipulación de Datos (5 horas) | F20: 2.1 | G20: =+'MODULO 2 '!D18 -> DataFrames. | H20: =+'MODULO 3'!B18 -> Unidad 2. Clasificación (5 horas) | I20: 2.1 | J20: =+'MODULO 3'!D18 -> Árboles de decisión. | K20: =+'MODULO 4'!B18 -> Unidad 2. APIs y Datos Abiertos (5 horas) | L20: 2.1 | M20: =+'MODULO 4'!D18 -> APIs REST. | N20: =+'MODULO 5'!B18 -> Unidad 2. Modelos Econométricos (5 horas) | O20: 2.1 | P20: =+'MODULO 5'!D18 -> Regresión econométrica. | Q20: =+'MODULO 6'!B18 -> Unidad 2. Modelos Bayesianos (5 horas) | R20: 2.1 | S20: =+'MODULO 6'!D18 -> Probabilidad bayesiana.
C21: 2.2 | D21: =+'MODULO 1 '!D19:H19 -> Tipos de inteligencia artificial. | F21: 2.2 | G21: =+'MODULO 2 '!D19 -> Limpieza de datos. | I21: 2.2 | J21: =+'MODULO 3'!D19 -> Random Forest. | L21: 2.2 | M21: =+'MODULO 4'!D19 -> Consumo de APIs. | O21: 2.2 | P21: =+'MODULO 5'!D19 -> Modelos ARIMA. | R21: 2.2 | S21: =+'MODULO 6'!D19 -> Inferencia bayesiana.
C22: 2.3 | D22: =+'MODULO 1 '!D20:H20 -> Aprendizaje supervisado. | F22: 2.3 | G22: =+'MODULO 2 '!D20 -> Transformación de variables. | I22: 2.3 | J22: =+'MODULO 3'!D20 -> SVM. | L22: 2.3 | M22: =+'MODULO 4'!D20 -> Datos abiertos. | O22: 2.3 | P22: =+'MODULO 5'!D20 -> VAR. | R22: 2.3 | S22: =+'MODULO 6'!D20 -> Redes bayesianas.
C23: 2.4 | D23: =+'MODULO 1 '!D21:H21 -> Aprendizaje no supervisado. | F23: 2.4 | G23: =+'MODULO 2 '!D21 -> Validación de datos. | I23: 2.4 | J23: =+'MODULO 3'!D21 -> KNN. | L23: 2.4 | M23: =+'MODULO 4'!D21 -> Integración de fuentes. | O23: 2.4 | P23: =+'MODULO 5'!D21 -> Cointegración. | R23: 2.4 | S23: =+'MODULO 6'!D21 -> Modelos probabilísticos.
C24: 2.5 | D24: =+'MODULO 1 '!D22:H22 -> Casos de uso. | F24: 2.5 | G24: =+'MODULO 2 '!D22 -> Integración de fuentes. | I24: 2.5 | J24: =+'MODULO 3'!D22 -> Métricas de clasificación. | L24: 2.5 | M24: =+'MODULO 4'!D22 -> Automatización de consultas. | O24: 2.5 | P24: =+'MODULO 5'!D22 -> Evaluación estadística. | R24: 2.5 | S24: =+'MODULO 6'!D22 -> Aplicaciones económicas.
B25: =+'MODULO 1 '!B23 -> Unidad 3. Machine Learning y Analítica (5 horas) | C25: 3.1 | D25: =+'MODULO 1 '!D23:H23 -> Modelos predictivos. | E25: =+'MODULO 2 '!B23 -> Unidad 3. Bases de Datos y ETL (5 horas) | F25: 3.1 | G25: =+'MODULO 2 '!D23 -> SQL básico. | H25: =+'MODULO 3'!B23 -> Unidad 3. Clustering y Segmentación (5 horas) | I25: 3.1 | J25: =+'MODULO 3'!D23 -> K-Means. | K25: =+'MODULO 4'!B23 -> Unidad 3. Automatización de Procesos (5 horas) | L25: 3.1 | M25: =+'MODULO 4'!D23 -> Scripts automatizados. | N25: =+'MODULO 5'!B23 -> Unidad 3. Forecasting con IA (5 horas) | O25: 3.1 | P25: =+'MODULO 5'!D23 -> Modelos predictivos. | Q25: =+'MODULO 6'!B23 -> Unidad 3. Introducción a Deep Learning (5 horas) | R25: 3.1 | S25: =+'MODULO 6'!D23 -> Redes neuronales.
C26: 3.2 | D26: =+'MODULO 1 '!D24:H24 -> Clasificación y regresión. | F26: 3.2 | G26: =+'MODULO 2 '!D24 -> Procesos ETL. | I26: 3.2 | J26: =+'MODULO 3'!D24 -> Clustering jerárquico. | L26: 3.2 | M26: =+'MODULO 4'!D24 -> Programación de tareas. | O26: 3.2 | P26: =+'MODULO 5'!D24 -> Forecasting híbrido. | R26: 3.2 | S26: =+'MODULO 6'!D24 -> TensorFlow.
C27: 3.3 | D27: =+'MODULO 1 '!D25:H25 -> Segmentación. | F27: 3.3 | G27: =+'MODULO 2 '!D25 -> Bases relacionales. | I27: 3.3 | J27: =+'MODULO 3'!D25 -> Segmentación económica. | L27: 3.3 | M27: =+'MODULO 4'!D25 -> Flujos ETL. | O27: 3.3 | P27: =+'MODULO 5'!D25 -> Redes neuronales básicas. | R27: 3.3 | S27: =+'MODULO 6'!D25 -> Keras.
C28: 3.4 | D28: =+'MODULO 1 '!D26:H26 -> Evaluación de modelos. | F28: 3.4 | G28: =+'MODULO 2 '!D26 -> Bases NoSQL. | I28: 3.4 | J28: =+'MODULO 3'!D26 -> Detección de patrones. | L28: 3.4 | M28: =+'MODULO 4'!D26 -> Automatización de reportes. | O28: 3.4 | P28: =+'MODULO 5'!D26 -> Evaluación predictiva. | R28: 3.4 | S28: =+'MODULO 6'!D26 -> Deep learning básico.
C29: 3.5 | D29: =+'MODULO 1 '!D27:H27 -> Interpretación de resultados. | F29: 3.5 | G29: =+'MODULO 2 '!D27 -> Integración de datos. | I29: 3.5 | J29: =+'MODULO 3'!D27 -> Interpretación de clusters | L29: 3.5 | M29: =+'MODULO 4'!D27 -> Integración de procesos. | O29: 3.5 | P29: =+'MODULO 5'!D27 -> Optimización de modelos. | R29: 3.5 | S29: =+'MODULO 6'!D27 -> Aplicaciones predictivas.
B30: =+'MODULO 1 '!B28 -> Unidad 4. IA aplicada a Economía (5 horas) | C30: 4.1 | D30: =+'MODULO 1 '!D28:H28 -> Analítica económica. | E30: =+'MODULO 2 '!B28 -> Unidad 4. Big Data Analytics (5 horas) | F30: 4.1 | G30: =+'MODULO 2 '!D28 -> Procesamiento masivo. | H30: =+'MODULO 3'!B28 -> Unidad 4. Reducción de Dimensionalidad (5 horas) | I30: 4.1 | J30: =+'MODULO 3'!D28 -> PCA. | K30: =+'MODULO 4'!B28 -> Unidad 4. Agentes Inteligentes (5 horas) | L30: 4.1 | M30: =+'MODULO 4'!D28 -> Introducción a agentes IA. | N30: =+'MODULO 5'!B28 -> Unidad 4. Pronóstico Macroeconómico (5 horas) | O30: 4.1 | P30: =+'MODULO 5'!D28 -> PIB. | Q30: =+'MODULO 6'!B28 -> Unidad 4. Aplicaciones Económicas Avanzadas (5 horas) | R30: 4.1 | S30: =+'MODULO 6'!D28 -> Analítica predictiva.
C31: 4.2 | D31: =+'MODULO 1 '!D29:H29 -> Variables macroeconómicas. | F31: 4.2 | G31: =+'MODULO 2 '!D29 -> Datos estructurados. | I31: 4.2 | J31: =+'MODULO 3'!D29 -> Selección de variables. | L31: 4.2 | M31: =+'MODULO 4'!D29 -> Procesamiento automático. | O31: 4.2 | P31: =+'MODULO 5'!D29 -> Inflación. Comercio exterior. Inversión pública y privada. Consumo de hogares. | R31: 4.2 | S31: =+'MODULO 6'!D29 -> Detección de anomalías.
C32: 4.3 | D32: =+'MODULO 1 '!D30:H30 -> Predicción económica. | F32: 4.3 | G32: =+'MODULO 2 '!D30 -> Datos no estructurados. | I32: 4.3 | J32: =+'MODULO 3'!D30 -> Ingeniería de características. | L32: 4.3 | M32: =+'MODULO 4'!D30 -> Automatización inteligente. | O32: 4.3 | P32: =+'MODULO 5'!D30 -> 0 | R32: 4.3 | S32: =+'MODULO 6'!D30 -> Segmentación económica.
C33: 4.4 | D33: =+'MODULO 1 '!D31:H31 -> Automatización de análisis. | F33: 4.4 | G33: =+'MODULO 2 '!D31 -> Introducción a Spark. | I33: 4.4 | J33: =+'MODULO 3'!D31 -> Visualización multidimensional. | L33: 4.4 | M33: =+'MODULO 4'!D31 -> Integración de modelos. | O33: 4.4 | P33: =+'MODULO 5'!D31 -> 0 | R33: 4.4 | S33: =+'MODULO 6'!D31 -> Riesgo financiero.
C34: 4.5 | D34: =+'MODULO 1 '!D32:H32 -> Innovación institucional. | F34: 4.5 | G34: =+'MODULO 2 '!D32 -> Analítica distribuida. | I34: 4.5 | J34: =+'MODULO 3'!D32 -> Optimización de modelos. | L34: 4.5 | M34: =+'MODULO 4'!D32 -> Casos institucionales. | O34: 4.5 | P34: =+'MODULO 5'!D32 -> 0 | R34: 4.5 | S34: =+'MODULO 6'!D32 -> Innovación institucional.
B35: =+'MODULO 1 '!B33 -> Unidad 5. Taller Introductorio (5 horas) | C35: 5.1 | D35: =+'MODULO 1 '!D33:H33 -> Laboratorio con Python. | E35: =+'MODULO 2 '!B33 -> Unidad 5. Taller de Programación (5 horas) | F35: 5.1 | G35: =+'MODULO 2 '!D33 -> Automatización de procesos. | H35: =+'MODULO 3'!B33 -> Unidad 5. Taller de Modelos Predictivos (5 horas) | I35: 5.1 | J35: =+'MODULO 3'!D33 -> Construcción de modelos. | K35: =+'MODULO 4'!B33 -> Unidad 5. Taller Integrador (5 horas) | L35: 5.1 | M35: =+'MODULO 4'!D33 -> Desarrollo de scraper. | N35: =+'MODULO 5'!B33 -> Unidad 5. Taller de Forecasting (5 horas) | O35: 5.1 | P35: =+'MODULO 5'!D33 -> Construcción de modelos. Comparación predictiva. Automatización de forecasting. Visualización de resultados. Presentación ejecutiva. | Q35: =+'MODULO 6'!B33 -> Unidad 5. Proyecto Final Integrador (5 horas) | R35: 5.1 | S35: =+'MODULO 6'!D33 -> Desarrollo de modelo avanzado.
C36: 5.2 | D36: =+'MODULO 1 '!D34:H34 -> Introducción a R. | F36: 5.2 | G36: =+'MODULO 2 '!D34 -> Scripts analíticos. | I36: 5.2 | J36: =+'MODULO 3'!D34 -> Evaluación comparativa. | L36: 5.2 | M36: =+'MODULO 4'!D34 -> Integración API. | O36: 5.2 | P36: =+'MODULO 5'!D34 -> 0 | R36: 5.2 | S36: =+'MODULO 6'!D34 -> Automatización de análisis.
C37: 5.3 | D37: =+'MODULO 1 '!D35:H35 -> Exploración de datos. | F37: 5.3 | G37: =+'MODULO 2 '!D35 -> Limpieza masiva. | I37: 5.3 | J37: =+'MODULO 3'!D35 -> Automatización de análisis. | L37: 5.3 | M37: =+'MODULO 4'!D35 -> Automatización analítica. | O37: 5.3 | P37: =+'MODULO 5'!D35 -> 0 | R37: 5.3 | S37: =+'MODULO 6'!D35 -> Visualización de resultados.
C38: 5.4 | D38: =+'MODULO 1 '!D36:H36 -> Visualización básica. | F38: 5.4 | G38: =+'MODULO 2 '!D36 -> Integración de datasets. | I38: 5.4 | J38: =+'MODULO 3'!D36 -> Forecasting económico. | L38: 5.4 | M38: =+'MODULO 4'!D36 -> Generación de reportes. | O38: 5.4 | P38: =+'MODULO 5'!D36 -> 0 | R38: 5.4 | S38: =+'MODULO 6'!D36 -> Presentación ejecutiva.
C39: 5.5 | D39: =+'MODULO 1 '!D37:H37 -> Ejercicios prácticos. | F39: 5.5 | G39: =+'MODULO 2 '!D37 -> Presentación de resultados. | I39: 5.5 | J39: =+'MODULO 3'!D37 -> Presentación de resultados. | L39: 5.5 | M39: =+'MODULO 4'!D37 -> Presentación de resultados. | O39: 5.5 | P39: =+'MODULO 5'!D37 -> 0 | R39: 5.5 | S39: =+'MODULO 6'!D37 -> Retroalimentación final.
A40: Realizado por: | I40: Fecha de Realización (dd-mm-aaa) | N40: Revisado por:
A41: Equipo de docentes del DIPLOMADO | I41: 46113 | N41: María del Mae
...

Sheet MODULO 1 
C1: UNIDAD DE CAPACITACIÓN Y CERTIFICACIÓN
C2: DISEÑO DE CONTENIDOS
B3: Código: CEC-RCYC-02;Revisión: 02
A4: Programa | B4: =+'RESUMEN DIPLOMADO'!D3 -> DIPLOMADO EN BIG DATA E INTELIGENCIA ARTIFICIAL | G4: Duración (Horas)
A5: Nombre del módulo | B5: MÓDULO 1. FUNDAMENTOS DE BIG DATA E INTELIGENCIA ARTIFICIAL | G5: Duración (Horas) | H5: 25 horas (20 horas sincrónicas y 5 horas asincrónicas)
A6: Presentación del módulo | B6: Este módulo introduce los conceptos fundamentales relacionados con Big Data, Inteligencia Artificial y Machine Learning, proporcionando una visión integral sobre el impacto de estas tecnologías en los procesos de análisis económico y toma de decisiones. Los participantes comprenderán los principales paradigmas de aprendizaje automático y su aplicación en escenarios institucionales. El módulo permitirá desarrollar capacidades para interpretar el ciclo de vida de proyectos de analítica avanzada y comprender el valor estratégico de los datos en organizaciones modernas. Los participantes adquirirán conocimientos sobre tipos de aprendizaje supervisado y no supervisado, ecosistemas de IA y aplicaciones en economía. Al finalizar, el estudiante será capaz de identificar oportunidades de implementación de IA y Big Data en contextos institucionales y económicos.
A7: Dirigido a | B7: Personal operativo, analistas económicos, estadísticos y profesionales vinculados al análisis de información.
A8: Requisitos académicos | B8: Conocimientos básicos de estadística, análisis de datos y herramientas informáticas.
A9: Requisitos técnicos | B9: Computador con 8 GB RAM. Navegador actualizado. Python y R instalados. Acceso a internet.
A10: Requisitos de aprobación | B10: Nota mínima para aprobar el curso: 70/100 Asistencia mínima: 80%
A11: Objetivo General | B11: Comprender los fundamentos de Big Data e Inteligencia Artificial mediante conceptos y herramientas tecnológicas en contextos de análisis económico, para identificar aplicaciones orientadas a la toma de decisiones basada en datos.
A12: Objetivos Específicos | B12: U1. Identificar conceptos fundamentales de IA mediante análisis de aplicaciones tecnológicas en contextos económicos para comprender su impacto institucional. U2. Analizar tipos de machine learning mediante modelos supervisados y no supervisados en escenarios analíticos para diferenciar enfoques predictivos. U3. Reconocer ecosistemas Big Data mediante plataformas y arquitecturas de datos en entornos organizacionales para comprender su funcionamiento. U4. Relacionar analítica avanzada mediante casos económicos institucionales para identificar oportunidades de innovación. Aplicar herramientas básicas de IA mediante laboratorios prácticos en análisis económico para interpretar resultados analíticos.
A13: Contenidos | B13: Unidad 1. Introducción a Big Data (5 horas) | C13: 1.1 | D13: Conceptos de Big Data.
C14: 1.2 | D14: Características de los datos masivos.
C15: 1.3 | D15: Ecosistemas de datos.
C16: 1.4 | D16: Transformación digital.
C17: 1.5 | D17: Aplicaciones institucionales.
B18: Unidad 2. Fundamentos de Inteligencia Artificial (5 horas) | C18: 2.1 | D18: Historia y evolución de la IA.
C19: 2.2 | D19: Tipos de inteligencia artificial.
C20: 2.3 | D20: Aprendizaje supervisado.
C21: 2.4 | D21: Aprendizaje no supervisado.
C22: 2.5 | D22: Casos de uso.
B23: Unidad 3. Machine Learning y Analítica (5 horas) | C23: 3.1 | D23: Modelos predictivos.
C24: 3.2 | D24: Clasificación y regresión.
C25: 3.3 | D25: Segmentación.
C26: 3.4 | D26: Evaluación de modelos.
C27: 3.5 | D27: Interpretación de resultados.
B28: Unidad 4. IA aplicada a Economía (5 horas) | C28: 4.1 | D28: Analítica económica.
C29: 4.2 | D29: Variables macroeconómicas.
C30: 4.3 | D30: Predicción económica.
C31: 4.4 | D31: Automatización de análisis.
C32: 4.5 | D32: Innovación institucional.
B33: Unidad 5. Taller Introductorio (5 horas) | C33: 5.1 | D33: Laboratorio con Python.
C34: 5.2 | D34: Introducción a R.
C35: 5.3 | D35: Exploración de datos.
C36: 5.4 | D36: Visualización básica.
C37: 5.5 | D37: Ejercicios prácticos.
A38: Metodología | B38: Se implementará Aprendizaje Basado en Problemas (ABP) mediante análisis de casos y ejercicios prácticos orientados a problemas reales de análisis económico y gestión de datos.0
A39: Evaluación | B39: Diagnóstica: | C39: 0% (identificación de conocimientos previos).
B40: Evaluación Formativa: | C40: 60% (participación en talleres, resolución de casos, actividades prácticas).
...

Sheet Plan de Clase M1
D1: UNIDAD DE CAPACITACIÓN Y CERTIFICACIÓN
D2: DISEÑO DE CONTENIDOS
D3: PLAN DE CLASE
B4: =+'MODULO 1 '!B3:H3 -> Código: CEC-RCYC-02;Revisión: 02
A5: Programa | B5: =+'MODULO 1 '!B4:F4 -> DIPLOMADO EN BIG DATA E INTELIGENCIA ARTIFICIAL | G5: Duración (Horas) | H5: =+'RESUMEN DIPLOMADO'!M3 -> 150 horas 120 horas sincrónicas y 30 horas asincrónicas
A6: Nombre del módulo | B6: =+'MODULO 1 '!B5:F5 -> MÓDULO 1. FUNDAMENTOS DE BIG DATA E INTELIGENCIA ARTIFICIAL | G6: Duración (Horas) | H6: =+'MODULO 1 '!H5 -> 25 horas (20 horas sincrónicas y 5 horas asincrónicas)
A7: Requisitos de aprobación | B7: Nota mínima para aprobar el curso: 70/100 Asistencia mínima: 80%
A8: Objetivo General | B8: =+'MODULO 1 '!B11:H11 -> Comprender los fundamentos de Big Data e Inteligencia Artificial mediante conceptos y herramientas tecnológicas en contextos de análisis económico, para identificar aplicaciones orientadas a la toma de decisiones basada en datos.
A9: Objetivos Específicos | B9: =+'MODULO 1 '!B12:H12 -> U1. Identificar conceptos fundamentales de IA mediante análisis de aplicaciones tecnológicas en contextos económicos para comprender su impacto institucional. U2. Analizar tipos de machine learning mediante modelos supervisados y no supervisados en escenarios analíticos para diferenciar enfoques predictivos. U3. Reconocer ecosistemas Big Data mediante plataformas y arquitecturas de datos en entornos organizacionales para comprender su funcionamiento. U4. Relacionar analítica avanzada mediante casos económicos institucionales para identificar oportunidades de innovación. Aplicar herramientas básicas de IA mediante laboratorios prácticos en análisis económico para interpretar resultados analíticos.
A10: =+'MODULO 1 '!B13 -> Unidad 1. Introducción a Big Data (5 horas) | B10: DIA | C10: Fecha (dd-mm-aaa) | D10: Contenidos | G10: Actividad de Aprendizaje | I10: Tipo de Evaluación
B11: 1 | C11: 45678 | D11: 1.1 | E11: =+'MODULO 1 '!D13 -> Conceptos de Big Data.
B12: 2 | D12: 1.2 | E12: =+'MODULO 1 '!D14 -> Características de los datos masivos.
B13: 3 | D13: 1.3 | E13: =+'MODULO 1 '!D15 -> Ecosistemas de datos.
D14: 1.4 | E14: =+'MODULO 1 '!D16 -> Transformación digital.
D15: 1.5 | E15: =+'MODULO 1 '!D17 -> Aplicaciones institucionales.
A16: =+'MODULO 1 '!B18 -> Unidad 2. Fundamentos de Inteligencia Artificial (5 horas) | D16: 2.1 | E16: =+'MODULO 1 '!D18 -> Historia y evolución de la IA.
D17: 2.2 | E17: =+'MODULO 1 '!D19 -> Tipos de inteligencia artificial.
D18: 2.3 | E18: =+'MODULO 1 '!D20 -> Aprendizaje supervisado.
D19: 2.4 | E19: =+'MODULO 1 '!D21 -> Aprendizaje no supervisado.
D20: 2.5 | E20: =+'MODULO 1 '!D22 -> Casos de uso.
A21: =+'MODULO 1 '!B23 -> Unidad 3. Machine Learning y Analítica (5 horas) | D21: 3.1 | E21: =+'MODULO 1 '!D23 -> Modelos predictivos.
D22: 3.2 | E22: =+'MODULO 1 '!D24 -> Clasificación y regresión.
D23: 3.3 | E23: =+'MODULO 1 '!D25 -> Segmentación.
D24: 3.4 | E24: =+'MODULO 1 '!D26 -> Evaluación de modelos.
D25: 3.5 | E25: =+'MODULO 1 '!D27 -> Interpretación de resultados.
A26: =+'MODULO 1 '!B28 -> Unidad 4. IA aplicada a Economía (5 horas) | D26: 4.1 | E26: =+'MODULO 1 '!D28 -> Analítica económica.
D27: 4.2 | E27: =+'MODULO 1 '!D29 -> Variables macroeconómicas.
D28: 4.3 | E28: =+'MODULO 1 '!D30 -> Predicción económica.
D29: 4.4 | E29: =+'MODULO 1 '!D31 -> Automatización de análisis.
D30: 4.5 | E30: =+'MODULO 1 '!D32 -> Innovación institucional.
A31: =+'MODULO 1 '!B33 -> Unidad 5. Taller Introductorio (5 horas) | D31: 5.1 | E31: =+'MODULO 1 '!D33 -> Laboratorio con Python.
D32: 5.2 | E32: =+'MODULO 1 '!D34 -> Introducción a R.
D33: 5.3 | E33: =+'MODULO 1 '!D35 -> Exploración de datos.
D34: 5.4 | E34: =+'MODULO 1 '!D36 -> Visualización básica.
D35: 5.5 | E35: =+'MODULO 1 '!D37 -> Ejercicios prácticos.
A36: Bibliografía | B36: =+'MODULO 1 '!B42:H42 -> Géron, A. (2022). Hands-On Machine Learning with Scikit-Learn, Keras, and TensorFlow. O'Reilly Media. https://www.oreilly.com Russell, S., & Norvig, P. (2021). Artificial Intelligence: A Modern Approach. Pearson. https://aima.cs.berkeley.edu Provost, F., & Fawcett, T. (2023). Data Science for Business. O'Reilly Media. https://www.oreilly.com
A37: Proceso de Evaluación | B37: Tipo de Evaluación | E37: Instrumento | G37: Núm de Actividades | H37: Puntaje por Actividad | I37: Puntaje Total
I38: =+G38*H38 -> 0
I39: =+G39*H39 -> 0
I40: =+G40*H40 -> 0
...

Sheet MODULO 2 
C1: UNIDAD DE CAPACITACIÓN Y CERTIFICACIÓN
C2: DISEÑO DE CONTENIDOS
B3: Código: CEC-RCYC-02;Revisión: 02
A4: Programa | B4: =+'RESUMEN DIPLOMADO'!D3 -> DIPLOMADO EN BIG DATA E INTELIGENCIA ARTIFICIAL | G4: Duración (Horas) | H4: =+'RESUMEN DIPLOMADO'!M3 -> 150 horas 120 horas sincrónicas y 30 horas asincrónicas
A5: Nombre del módulo | B5: MÓDULO 2. PROGRAMACIÓN Y GESTIÓN DE DATOS MASIVOS | G5: Duración (Horas) | H5: 25 horas (20 horas sincrónicas y 5 horas asincrónicas)
A6: Presentación del curso | B6: Este módulo desarrolla competencias relacionadas con programación orientada al análisis de datos, gestión de bases de datos masivas y procesamiento de información estructurada y no estructurada. Los participantes aprenderán técnicas de limpieza, transformación y manipulación de datos utilizando R y Python. La propuesta de valor del módulo radica en fortalecer capacidades técnicas para automatizar procesos de análisis y preparación de datos, optimizando la calidad de la información utilizada en estudios económicos y estadísticos. Al finalizar, los estudiantes estarán en capacidad de desarrollar flujos de procesamiento de datos y construir estructuras de análisis reproducibles.
A7: Dirigido a | B7: Analistas de datos, estadísticos, economistas y profesionales vinculados al procesamiento de información.
A8: Requisitos académicos | B8: Conocimientos básicos de programación y estadística descriptiva.
A9: Requisitos técnicos | B9: Computador con 8 GB RAM. Python y R instalados. Acceso a internet. Jupyter Notebook.
A10: Requisitos de aprobación | B10: Nota mínima para aprobar el curso: 70/100 Asistencia mínima: 80%
A11: Objetivo General | B11: Gestionar datos masivos mediante herramientas de programación y procesamiento en contextos analíticos institucionales, para optimizar la calidad y disponibilidad de información económica.
A12: Objetivos Específicos | B12: U1. Aplicar fundamentos de programación mediante R y Python en escenarios analíticos para automatizar procesos de datos. U2. Gestionar bases de datos mediante técnicas ETL en entornos institucionales para optimizar calidad de información. U2. Limpiar y transformar datos mediante librerías analíticas en proyectos económicos para mejorar consistencia de resultados. U3. Analizar datos estructurados y no estructurados mediante herramientas de procesamiento para generar información útil. U4. Desarrollar flujos automatizados mediante programación aplicada en casos institucionales para optimizar análisis económico.
A13: Contenidos | B13: Unidad 1. Programación en Python y R (5 horas) | C13: 1.1 | D13: Sintaxis básica.
C14: 1.2 | D14: Variables y estructuras.
C15: 1.3 | D15: Funciones.
C16: 1.4 | D16: Librerías analíticas.
C17: 1.5 | D17: Automatización básica.
B18: Unidad 2. Manipulación de Datos (5 horas) | C18: 2.1 | D18: DataFrames.
C19: 2.2 | D19: Limpieza de datos.
C20: 2.3 | D20: Transformación de variables.
C21: 2.4 | D21: Validación de datos.
C22: 2.5 | D22: Integración de fuentes.
B23: Unidad 3. Bases de Datos y ETL (5 horas) | C23: 3.1 | D23: SQL básico.
C24: 3.2 | D24: Procesos ETL.
C25: 3.3 | D25: Bases relacionales.
C26: 3.4 | D26: Bases NoSQL.
C27: 3.5 | D27: Integración de datos.
B28: Unidad 4. Big Data Analytics (5 horas) | C28: 4.1 | D28: Procesamiento masivo.
C29: 4.2 | D29: Datos estructurados.
C30: 4.3 | D30: Datos no estructurados.
C31: 4.4 | D31: Introducción a Spark.
C32: 4.5 | D32: Analítica distribuida.
B33: Unidad 5. Taller de Programación (5 horas) | C33: 5.1 | D33: Automatización de procesos.
C34: 5.2 | D34: Scripts analíticos.
C35: 5.3 | D35: Limpieza masiva.
C36: 5.4 | D36: Integración de datasets.
C37: 5.5 | D37: Presentación de resultados.
A38: Metodología | B38: Se utilizará Flipped Classroom mediante revisión previa de contenidos teóricos y sesiones prácticas enfocadas en programación aplicada y resolución de ejercicios.0
A39: Evaluación | B39: Diagnóstica: | C39: 0% (identificación de conocimientos previos).
B40: Evaluación Formativa: | C40: 60% (participación en talleres, resolución de casos, actividades prácticas).
...

Sheet Plan de Clase M2
D1: UNIDAD DE CAPACITACIÓN Y CERTIFICACIÓN
D2: DISEÑO DE CONTENIDOS
D3: PLAN DE CLASE
B4: =+'MODULO 2 '!B3:H3 -> Código: CEC-RCYC-02;Revisión: 02
A5: Programa | B5: =+'RESUMEN DIPLOMADO'!D3 -> DIPLOMADO EN BIG DATA E INTELIGENCIA ARTIFICIAL | G5: Duración (Horas) | H5: =+'RESUMEN DIPLOMADO'!M3 -> 150 horas 120 horas sincrónicas y 30 horas asincrónicas
A6: Nombre del módulo | B6: =+'MODULO 2 '!B5:F5 -> MÓDULO 2. PROGRAMACIÓN Y GESTIÓN DE DATOS MASIVOS | G6: Duración (Horas) | H6: =+'MODULO 2 '!H5 -> 25 horas (20 horas sincrónicas y 5 horas asincrónicas)
A7: Requisitos de aprobación | B7: Nota mínima para aprobar el curso: 70/100 Asistencia mínima: 80%
A8: Objetivo General | B8: =+'MODULO 2 '!B11:H11 -> Gestionar datos masivos mediante herramientas de programación y procesamiento en contextos analíticos institucionales, para optimizar la calidad y disponibilidad de información económica.
A9: Objetivos Específicos | B9: =+'MODULO 2 '!B12:H12 -> U1. Aplicar fundamentos de programación mediante R y Python en escenarios analíticos para automatizar procesos de datos. U2. Gestionar bases de datos mediante técnicas ETL en entornos institucionales para optimizar calidad de información. U2. Limpiar y transformar datos mediante librerías analíticas en proyectos económicos para mejorar consistencia de resultados. U3. Analizar datos estructurados y no estructurados mediante herramientas de procesamiento para generar información útil. U4. Desarrollar flujos automatizados mediante programación aplicada en casos institucionales para optimizar análisis económico.
A10: =+'MODULO 2 '!B13 -> Unidad 1. Programación en Python y R (5 horas) | B10: DIA | C10: Fecha (dd-mm-aaa) | D10: Contenidos | G10: Actividad de Aprendizaje | I10: Tipo de Evaluación
B11: 1 | D11: 1.1 | E11: =+'MODULO 2 '!D13 -> Sintaxis básica.
B12: 2 | D12: 1.2 | E12: =+'MODULO 2 '!D14 -> Variables y estructuras.
B13: 3 | D13: 1.3 | E13: =+'MODULO 2 '!D15 -> Funciones.
D14: 1.4 | E14: =+'MODULO 2 '!D16 -> Librerías analíticas.
D15: 1.5 | E15: =+'MODULO 2 '!D17 -> Automatización básica.
A16: =+'MODULO 2 '!B18 -> Unidad 2. Manipulación de Datos (5 horas) | D16: 2.1 | E16: =+'MODULO 2 '!D18 -> DataFrames.
D17: 2.2 | E17: =+'MODULO 2 '!D19 -> Limpieza de datos.
D18: 2.3 | E18: =+'MODULO 2 '!D20 -> Transformación de variables.
D19: 2.4 | E19: =+'MODULO 2 '!D21 -> Validación de datos.
D20: 2.5 | E20: =+'MODULO 2 '!D22 -> Integración de fuentes.
A21: =+'MODULO 2 '!B23 -> Unidad 3. Bases de Datos y ETL (5 horas) | D21: 3.1 | E21: =+'MODULO 2 '!D23 -> SQL básico.
D22: 3.2 | E22: =+'MODULO 2 '!D24 -> Procesos ETL.
D23: 3.3 | E23: =+'MODULO 2 '!D25 -> Bases relacionales.
D24: 3.4 | E24: =+'MODULO 2 '!D26 -> Bases NoSQL.
D25: 3.5 | E25: =+'MODULO 2 '!D27 -> Integración de datos.
A26: =+'MODULO 2 '!B28 -> Unidad 4. Big Data Analytics (5 horas) | D26: 4.1 | E26: =+'MODULO 2 '!D28 -> Procesamiento masivo.
D27: 4.2 | E27: =+'MODULO 2 '!D29 -> Datos estructurados.
D28: 4.3 | E28: =+'MODULO 2 '!D30 -> Datos no estructurados.
D29: 4.4 | E29: =+'MODULO 2 '!D31 -> Introducción a Spark.
D30: 4.5 | E30: =+'MODULO 2 '!D32 -> Analítica distribuida.
A31: =+'MODULO 2 '!B33 -> Unidad 5. Taller de Programación (5 horas) | D31: 5.1 | E31: =+'MODULO 2 '!D33 -> Automatización de procesos.
D32: 5.2 | E32: =+'MODULO 2 '!D34 -> Scripts analíticos.
D33: 5.3 | E33: =+'MODULO 2 '!D35 -> Limpieza masiva.
D34: 5.4 | E34: =+'MODULO 2 '!D36 -> Integración de datasets.
D35: 5.5 | E35: =+'MODULO 2 '!D37 -> Presentación de resultados.
A36: Bibliografía | B36: =+'MODULO 2 '!B42:H42 -> Wickham, H. (2023). R for Data Science. O'Reilly Media. https://r4ds.hadley.nz McKinney, W. (2022). Python for Data Analysis. O'Reilly Media. https://wesmckinney.com/book/ Zaharia, M. (2021). Learning Spark. O'Reilly Media. https://www.oreilly.com
A37: Proceso de Evaluación | B37: Tipo de Evaluación | E37: Instrumento | G37: Núm de Actividades | H37: Puntaje por Actividad | I37: Puntaje Total
I38: =+G38*H38 -> 0
I39: =+G39*H39 -> 0
I40: =+G40*H40 -> 0
...

Sheet MODULO 3
C1: UNIDAD DE CAPACITACIÓN Y CERTIFICACIÓN
C2: DISEÑO DE CONTENIDOS
B3: Código: CEC-RCYC-02;Revisión: 02
A4: Programa | B4: =+'RESUMEN DIPLOMADO'!D3 -> DIPLOMADO EN BIG DATA E INTELIGENCIA ARTIFICIAL | G4: Duración (Horas) | H4: =+'RESUMEN DIPLOMADO'!M3 -> 150 horas 120 horas sincrónicas y 30 horas asincrónicas
A5: Nombre del módulo | B5: MÓDULO 3. MACHINE LEARNING APLICADO | G5: Duración (Horas) | H5: 25 horas (20 horas sincrónicas y 5 horas asincrónicas)
A6: Presentación del curso | B6: Este módulo aborda las técnicas de machine learning aplicadas al análisis predictivo, clasificación y segmentación de datos económicos. Los participantes desarrollarán modelos supervisados y no supervisados utilizando herramientas modernas de ciencia de datos. El módulo permitirá fortalecer competencias analíticas para generar modelos predictivos orientados a forecasting económico y toma de decisiones. Al finalizar, los participantes podrán construir modelos de regresión, clasificación y clustering aplicados a problemas institucionales y económicos.
A7: Dirigido a | B7: Analistas económicos, científicos de datos y profesionales vinculados al análisis predictivo.
A8: Requisitos académicos | B8: Conocimientos básicos de programación, estadística y análisis de datos.
A9: Requisitos técnicos | B9: Computador con 8 GB RAM. Python instalado. Librerías de machine learning. Conectividad estable.
A10: Requisitos de aprobación | B10: Nota mínima para aprobar el curso: 70/100 Asistencia mínima: 80%
A11: Objetivo General | B11: Aplicar modelos de machine learning mediante técnicas predictivas y herramientas analíticas en escenarios económicos, para generar pronósticos y clasificaciones basadas en datos.
A12: Objetivos Específicos | B12: Construir modelos de regresión mediante algoritmos supervisados en análisis económicos para generar predicciones. Aplicar técnicas de clasificación mediante machine learning en conjuntos de datos institucionales para identificar patrones. Implementar modelos de clustering mediante algoritmos no supervisados en análisis de segmentación para interpretar comportamientos. Evaluar desempeño de modelos mediante métricas analíticas en proyectos predictivos para optimizar resultados. Desarrollar soluciones predictivas mediante laboratorios aplicados en escenarios económicos para fortalecer toma de decisiones.
A13: Contenidos | B13: Unidad 1. Regresión y Predicción (5 horas) | C13: 1.1 | D13: Regresión lineal.
C14: 1.2 | D14: Regresión múltiple.
C15: 1.3 | D15: Evaluación predictiva.
C16: 1.4 | D16: Overfitting.
C17: 1.5 | D17: Validación cruzada.
B18: Unidad 2. Clasificación (5 horas) | C18: 2.1 | D18: Árboles de decisión.
C19: 2.2 | D19: Random Forest.
C20: 2.3 | D20: SVM.
C21: 2.4 | D21: KNN.
C22: 2.5 | D22: Métricas de clasificación.
B23: Unidad 3. Clustering y Segmentación (5 horas) | C23: 3.1 | D23: K-Means.
C24: 3.2 | D24: Clustering jerárquico.
C25: 3.3 | D25: Segmentación económica.
C26: 3.4 | D26: Detección de patrones.
C27: 3.5 | D27: Interpretación de clusters
B28: Unidad 4. Reducción de Dimensionalidad (5 horas) | C28: 4.1 | D28: PCA.
C29: 4.2 | D29: Selección de variables.
C30: 4.3 | D30: Ingeniería de características.
C31: 4.4 | D31: Visualización multidimensional.
C32: 4.5 | D32: Optimización de modelos.
B33: Unidad 5. Taller de Modelos Predictivos (5 horas) | C33: 5.1 | D33: Construcción de modelos.
C34: 5.2 | D34: Evaluación comparativa.
C35: 5.3 | D35: Automatización de análisis.
C36: 5.4 | D36: Forecasting económico.
C37: 5.5 | D37: Presentación de resultados.
A38: Metodología | B38: Se aplicará Aprendizaje Cooperativo mediante laboratorios grupales y desarrollo de modelos predictivos colaborativos.0
A39: Evaluación | B39: Diagnóstica: | C39: 0% (identificación de conocimientos previos).
B40: Evaluación Formativa: | C40: 60% (participación en talleres, resolución de casos, actividades prácticas).
...

Sheet Plan de Clase M3
D1: UNIDAD DE CAPACITACIÓN Y CERTIFICACIÓN
D2: DISEÑO DE CONTENIDOS
D3: PLAN DE CLASE
B4: =+'MODULO 3'!B3:H3 -> Código: CEC-RCYC-02;Revisión: 02
A5: Programa | B5: =+'RESUMEN DIPLOMADO'!D3 -> DIPLOMADO EN BIG DATA E INTELIGENCIA ARTIFICIAL | G5: Duración (Horas) | H5: =+'RESUMEN DIPLOMADO'!M3 -> 150 horas 120 horas sincrónicas y 30 horas asincrónicas
A6: Nombre del módulo | B6: =+'MODULO 1 '!B5:F5 -> MÓDULO 1. FUNDAMENTOS DE BIG DATA E INTELIGENCIA ARTIFICIAL | G6: Duración (Horas) | H6: =+'MODULO 3'!H5 -> 25 horas (20 horas sincrónicas y 5 horas asincrónicas)
A7: Requisitos de aprobación | B7: Nota mínima para aprobar el curso: 70/100 Asistencia mínima: 80%
A8: Objetivo General | B8: =+'MODULO 1 '!B11:H11 -> Comprender los fundamentos de Big Data e Inteligencia Artificial mediante conceptos y herramientas tecnológicas en contextos de análisis económico, para identificar aplicaciones orientadas a la toma de decisiones basada en datos.
A9: Objetivos Específicos | B9: =+'MODULO 1 '!B12:H12 -> U1. Identificar conceptos fundamentales de IA mediante análisis de aplicaciones tecnológicas en contextos económicos para comprender su impacto institucional. U2. Analizar tipos de machine learning mediante modelos supervisados y no supervisados en escenarios analíticos para diferenciar enfoques predictivos. U3. Reconocer ecosistemas Big Data mediante plataformas y arquitecturas de datos en entornos organizacionales para comprender su funcionamiento. U4. Relacionar analítica avanzada mediante casos económicos institucionales para identificar oportunidades de innovación. Aplicar herramientas básicas de IA mediante laboratorios prácticos en análisis económico para interpretar resultados analíticos.
A10: =+'MODULO 3'!B13 -> Unidad 1. Regresión y Predicción (5 horas) | B10: DIA | C10: Fecha (dd-mm-aaa) | D10: Contenidos | G10: Actividad de Aprendizaje | I10: Tipo de Evaluación
B11: 1 | C11: 46308 | D11: 1.1 | E11: =+'MODULO 3'!D13 -> Regresión lineal. | G11: Práctica guiada con datos económicos y cuestionario breve para conocer el punto de partida del grupo. | I11: Diagnóstica
B12: 1 | C12: 46308 | D12: 1.2 | E12: =+'MODULO 3'!D14 -> Regresión múltiple.
B13: 1 | C13: 46308 | D13: 1.3 | E13: =+'MODULO 3'!D15 -> Evaluación predictiva.
B14: 2 | C14: 46309 | D14: 1.4 | E14: =+'MODULO 3'!D16 -> Overfitting. | G14: Laboratorio guiado: comparar errores de Train y Validation en regresión lineal, árbol y bosque de regresión. Preguntas de reflexión sobre la complejidad del modelo.
B15: 2 | C15: 46309 | D15: 1.5 | E15: =+'MODULO 3'!D17 -> Validación cruzada.
A16: =+'MODULO 3'!B18 -> Unidad 2. Clasificación (5 horas) | B16: 2 | C16: 46309 | D16: 2.1 | E16: =+'MODULO 3'!D18 -> Árboles de decisión.
B17: 3 | C17: 46310 | D17: 2.2 | E17: =+'MODULO 3'!D19 -> Random Forest. | G17: Estudio de caso y laboratorio guiado con Bank Marketing: problema yes/no, desbalance, baseline, Gini y matriz de confusión; comparación colaborativa de cuatro clasificadores sobre la misma Validation.
B18: 3 | C18: 46310 | D18: 2.3 | E18: =+'MODULO 3'!D20 -> SVM.
B19: 3 | C19: 46310 | D19: 2.4 | E19: =+'MODULO 3'!D21 -> KNN.
B20: 3 | C20: 46310 | D20: 2.5 | E20: =+'MODULO 3'!D22 -> Métricas de clasificación.
A21: =+'MODULO 3'!B23 -> Unidad 3. Clustering y Segmentación (5 horas) | B21: 4 | C21: 46311 | D21: 3.1 | E21: =+'MODULO 3'!D23 -> K-Means. | G21: Laboratorio guiado y Proyecto Integrador, parte 1 — avance 1: elegir uno de los cinco datasets, formular la pregunta, justificar si es regresión, clasificación o clustering y explicar fuente, unidad de observación, columnas y respuesta buscada. | I21: Formativa
B22: 4 | C22: 46311 | D22: 3.2 | E22: =+'MODULO 3'!D24 -> Clustering jerárquico.
B23: 4 | C23: 46311 | D23: 3.3 | E23: =+'MODULO 3'!D25 -> Segmentación económica.
B24: 4 | C24: 46311 | D24: 3.4 | E24: =+'MODULO 3'!D26 -> Detección de patrones.
B25: 4 | C25: 46311 | D25: 3.5 | E25: =+'MODULO 3'!D27 -> Interpretación de clusters
A26: =+'MODULO 3'!B28 -> Unidad 4. Reducción de Dimensionalidad (5 horas) | B26: 5 | C26: 46312 | D26: 4.1 | E26: =+'MODULO 3'!D28 -> PCA. | G26: Laboratorio guiado y Proyecto Integrador, parte 1 — avance 2 (15 puntos): examinar tipos de datos, faltantes y duplicados; justificar limpieza; presentar al menos tres gráficos; definir Train/Validation/Test. Identificar variables cualitativas y codificarlas con One-Hot ajustado solo en Train, cuando sean predictoras pertinentes. | I26: Formativa
B27: 5 | C27: 46312 | D27: 4.2 | E27: =+'MODULO 3'!D29 -> Selección de variables.
B28: 5 | C28: 46312 | D28: 4.3 | E28: =+'MODULO 3'!D30 -> Ingeniería de características.
B29: 6 | C29: 46313 | D29: 4.4 | E29: =+'MODULO 3'!D31 -> Visualización multidimensional. | G29: Laboratorio guiado y Proyecto Integrador, parte 1 — avance 3: construir baseline y modelos, comparar en Validation, revisar gráficos, métricas o estabilidad según el tipo de problema y dejar fijada la decisión antes de Test. | I29: Formativa
B30: 6 | C30: 46313 | D30: 4.5 | E30: =+'MODULO 3'!D32 -> Optimización de modelos.
A31: =+'MODULO 3'!B33 -> Unidad 5. Taller de Modelos Predictivos (5 horas) | B31: 6 | C31: 46313 | D31: 5.1 | E31: =+'MODULO 3'!D33 -> Construcción de modelos.
B32: 6 | C32: 46313 | D32: 5.2 | E32: =+'MODULO 3'!D34 -> Evaluación comparativa.
B33: 7 | C33: 46314 | D33: 5.3 | E33: =+'MODULO 3'!D35 -> Automatización de análisis. | G33: Proyecto Integrador, parte 2 — práctica final: entregar notebook reproducible, evaluar el Test reservado o la estabilidad final de clustering, interpretar resultados y limitaciones, y presentar una conclusión sustentada. El ejemplo guiado de forecasting forma parte de la jornada. | I33: Final
B34: 7 | C34: 46314 | D34: 5.4 | E34: =+'MODULO 3'!D36 -> Forecasting económico.
B35: 7 | C35: 46314 | D35: 5.5 | E35: =+'MODULO 3'!D37 -> Presentación de resultados.
A36: Bibliografía | B36: =+'MODULO 3'!B42:H42 -> Hastie, T., Tibshirani, R., & Friedman, J. (2021). The Elements of Statistical Learning. Springer. https://hastie.su.domains/ElemStatLearn/ James, G. et al. (2023). An Introduction to Statistical Learning. Springer. https://www.statlearning.com Géron, A. (2022). Hands-On Machine Learning with Scikit-Learn, Keras, and TensorFlow. O'Reilly Media. https://www.oreilly.com
A37: Proceso de Evaluación | B37: Tipo de Evaluación | E37: Instrumento | G37: Núm de Actividades | H37: Puntaje por Actividad | I37: Puntaje Total
B38: Diagnóstica | E38: Cuestionario breve de conocimientos previos | G38: 1 | H38: 0 | I38: =+G38*H38 -> 0
B39: Formativa | E39: Proyecto Integrador | G39: 3 | H39: 20 | I39: =+G39*H39 -> 60
B40: Final | E40: Proyecto Integrador | G40: 1 | H40: 40 | I40: =+G40*H40 -> 40
...

Sheet MODULO 4
C1: UNIDAD DE CAPACITACIÓN Y CERTIFICACIÓN
C2: DISEÑO DE CONTENIDOS
B3: Código: CEC-RCYC-02;Revisión: 02
A4: Programa | B4: =+'RESUMEN DIPLOMADO'!D3 -> DIPLOMADO EN BIG DATA E INTELIGENCIA ARTIFICIAL | G4: Duración (Horas) | H4: =+'RESUMEN DIPLOMADO'!M3 -> 150 horas 120 horas sincrónicas y 30 horas asincrónicas
A5: Nombre del curso | B5: MÓDULO 4. IA PARA AUTOMATIZACIÓN Y RECOLECCIÓN DE DATOS | G5: Duración (Horas) | H5: 25 horas (20 horas sincrónicas y 5 horas asincrónicas)
A6: Presentación del curso | B6: Este módulo desarrolla competencias para automatizar procesos de captura, integración y procesamiento de información mediante herramientas de inteligencia artificial, APIs y web scraping. Los participantes aprenderán a construir flujos automatizados para la obtención y procesamiento de datos económicos. El módulo permitirá optimizar procesos institucionales relacionados con actualización de bases de datos, monitoreo de indicadores y generación automática de reportes. Al finalizar, los estudiantes estarán en capacidad de implementar soluciones automatizadas para recolección y análisis de información.
A7: Dirigido a | B7: Analistas de información, economistas, estadísticos y profesionales TIC.
A8: Requisitos académicos | B8: Conocimientos básicos de programación y análisis de datos.
A9: Requisitos técnicos | B9: Computador con 8 GB RAM. Python instalado. Navegador actualizado. Acceso a internet.
A10: Requisitos de aprobación | B10: Nota mínima para aprobar el curso: 70/100 Asistencia mínima: 80%
A11: Objetivo General | B11: Automatizar procesos de recolección y procesamiento de datos mediante herramientas de IA y programación en contextos analíticos institucionales, para optimizar generación de información económica.
A12: Objetivos Específicos | B12: U1. Implementar técnicas de web scraping mediante programación en plataformas web para automatizar captura de información. U2. Utilizar APIs mediante herramientas tecnológicas en análisis económicos para integrar fuentes de datos. U3. Automatizar procesos analíticos mediante scripts y flujos de trabajo en escenarios institucionales para optimizar productividad. U4. Aplicar agentes inteligentes mediante herramientas de IA en procesos de datos para mejorar eficiencia operativa. U5. Desarrollar soluciones automatizadas mediante casos prácticos institucionales para fortalecer análisis económico.
A13: Contenidos | B13: Unidad 1. Web Scraping (5 horas) | C13: 1.1 | D13: Introducción al scraping.
C14: 1.2 | D14: BeautifulSoup.
C15: 1.3 | D15: Selenium.
C16: 1.4 | D16: Extracción de tablas.
C17: 1.5 | D17: Automatización web.
B18: Unidad 2. APIs y Datos Abiertos (5 horas) | C18: 2.1 | D18: APIs REST.
C19: 2.2 | D19: Consumo de APIs.
C20: 2.3 | D20: Datos abiertos.
C21: 2.4 | D21: Integración de fuentes.
C22: 2.5 | D22: Automatización de consultas.
B23: Unidad 3. Automatización de Procesos (5 horas) | C23: 3.1 | D23: Scripts automatizados.
C24: 3.2 | D24: Programación de tareas.
C25: 3.3 | D25: Flujos ETL.
C26: 3.4 | D26: Automatización de reportes.
C27: 3.5 | D27: Integración de procesos.
B28: Unidad 4. Agentes Inteligentes (5 horas) | C28: 4.1 | D28: Introducción a agentes IA.
C29: 4.2 | D29: Procesamiento automático.
C30: 4.3 | D30: Automatización inteligente.
C31: 4.4 | D31: Integración de modelos.
C32: 4.5 | D32: Casos institucionales.
B33: Unidad 5. Taller Integrador (5 horas) | C33: 5.1 | D33: Desarrollo de scraper.
C34: 5.2 | D34: Integración API.
C35: 5.3 | D35: Automatización analítica.
C36: 5.4 | D36: Generación de reportes.
C37: 5.5 | D37: Presentación de resultados.
A38: Metodología | B38: Se implementará Design Thinking mediante retos de automatización orientados a resolver problemas institucionales reales.0
A39: Evaluación | B39: Diagnóstica: | C39: Diagnóstica: 0%
B40: Evaluación Formativa: | C40: Formativa: 60% (participación, talleres, proyectos, estudios de caso)
...

Sheet Plan de Clase M4
D1: UNIDAD DE CAPACITACIÓN Y CERTIFICACIÓN
D2: DISEÑO DE CONTENIDOS
D3: PLAN DE CLASE
B4: =+'MODULO 4'!B3:H3 -> Código: CEC-RCYC-02;Revisión: 02
A5: Programa | B5: =+'RESUMEN DIPLOMADO'!D3 -> DIPLOMADO EN BIG DATA E INTELIGENCIA ARTIFICIAL | G5: Duración (Horas) | H5: =+'RESUMEN DIPLOMADO'!M3 -> 150 horas 120 horas sincrónicas y 30 horas asincrónicas
A6: Nombre del módulo | B6: =+'MODULO 4'!B5:F5 -> MÓDULO 4. IA PARA AUTOMATIZACIÓN Y RECOLECCIÓN DE DATOS | G6: Duración (Horas) | H6: =+'MODULO 4'!H5 -> 25 horas (20 horas sincrónicas y 5 horas asincrónicas)
A7: Requisitos de aprobación | B7: Nota mínima para aprobar el curso: 70/100 Asistencia mínima: 80%
A8: Objetivo General | B8: =+'MODULO 4'!B11:H11 -> Automatizar procesos de recolección y procesamiento de datos mediante herramientas de IA y programación en contextos analíticos institucionales, para optimizar generación de información económica.
A9: Objetivos Específicos | B9: =+'MODULO 4'!B12:H12 -> U1. Implementar técnicas de web scraping mediante programación en plataformas web para automatizar captura de información. U2. Utilizar APIs mediante herramientas tecnológicas en análisis económicos para integrar fuentes de datos. U3. Automatizar procesos analíticos mediante scripts y flujos de trabajo en escenarios institucionales para optimizar productividad. U4. Aplicar agentes inteligentes mediante herramientas de IA en procesos de datos para mejorar eficiencia operativa. U5. Desarrollar soluciones automatizadas mediante casos prácticos institucionales para fortalecer análisis económico.
A10: =+'MODULO 4'!B13 -> Unidad 1. Web Scraping (5 horas) | B10: DIA | C10: Fecha (dd-mm-aaa) | D10: Contenidos | G10: Actividad de Aprendizaje | I10: Tipo de Evaluación
B11: 1 | D11: 1.1 | E11: =+'MODULO 4'!D13 -> Introducción al scraping.
B12: 2 | D12: 1.2 | E12: =+'MODULO 4'!D14 -> BeautifulSoup.
B13: 3 | D13: 1.3 | E13: =+'MODULO 4'!D15 -> Selenium.
D14: 1.4 | E14: =+'MODULO 4'!D16 -> Extracción de tablas.
D15: 1.5 | E15: =+'MODULO 4'!D17 -> Automatización web.
A16: =+'MODULO 4'!B18 -> Unidad 2. APIs y Datos Abiertos (5 horas) | D16: 2.1 | E16: =+'MODULO 4'!D18 -> APIs REST.
D17: 2.2 | E17: =+'MODULO 4'!D19 -> Consumo de APIs.
D18: 2.3 | E18: =+'MODULO 4'!D20 -> Datos abiertos.
D19: 2.4 | E19: =+'MODULO 4'!D21 -> Integración de fuentes.
D20: 2.5 | E20: =+'MODULO 4'!D22 -> Automatización de consultas.
A21: =+'MODULO 4'!B23 -> Unidad 3. Automatización de Procesos (5 horas) | D21: 3.1 | E21: =+'MODULO 4'!D23 -> Scripts automatizados.
D22: 3.2 | E22: =+'MODULO 4'!D24 -> Programación de tareas.
D23: 3.3 | E23: =+'MODULO 4'!D25 -> Flujos ETL.
D24: 3.4 | E24: =+'MODULO 4'!D26 -> Automatización de reportes.
D25: 3.5 | E25: =+'MODULO 4'!D27 -> Integración de procesos.
A26: =+'MODULO 4'!B28 -> Unidad 4. Agentes Inteligentes (5 horas) | D26: 4.1 | E26: =+'MODULO 4'!D28 -> Introducción a agentes IA.
D27: 4.2 | E27: =+'MODULO 4'!D29 -> Procesamiento automático.
D28: 4.3 | E28: =+'MODULO 4'!D30 -> Automatización inteligente.
D29: 4.4 | E29: =+'MODULO 4'!D31 -> Integración de modelos.
D30: 4.5 | E30: =+'MODULO 4'!D32 -> Casos institucionales.
A31: =+'MODULO 4'!B33 -> Unidad 5. Taller Integrador (5 horas) | D31: 5.1 | E31: =+'MODULO 4'!D33 -> Desarrollo de scraper.
D32: 5.2 | E32: =+'MODULO 4'!D34 -> Integración API.
D33: 5.3 | E33: =+'MODULO 4'!D35 -> Automatización analítica.
D34: 5.4 | E34: =+'MODULO 4'!D36 -> Generación de reportes.
D35: 5.5 | E35: =+'MODULO 4'!D37 -> Presentación de resultados.
